错误处理
1.
高级语言通常都内置了一套try...except...finally...的错误处理机制，Python也不例外

2.
try:
    print('try...')
    r = 10 / 0
    print('result:', r)
except ZeroDivisionError as e:
    print('except:', e)
finally:
    print('finally...')
print('END')
当我们认为某些代码可能会出错时，就可以用try来运行这段代码，如果执行出错，则后续代码不会继续执行，而是直接跳转至错误处理代码，即except语句块，执行完except后，如果有finally语句块，则执行finally语句块，至此，执行完毕。
当我们认为某些代码可能会出错时，就可以用try来运行这段代码，如果执行出错，则后续代码不会继续执行，而是直接跳转至错误处理代码，即except语句块，执行完except后，如果有finally语句块，则执行finally语句块，至此，执行完毕。
如果没有错误发生，所以except语句块不会被执行，但是finally如果有，则一定会被执行（可以没有finally语句）。

3.
except语句块用来捕捉错误。
不同类型的错误：ZeroDivisionError，ValueError

4.
如果没有错误发生，可以在except语句块后面加一个else，当没有错误发生时，会自动执行else语句

5.
Python的错误其实也是class，所有的错误类型都继承自BaseException，所以在使用except时需要注意的是，它不但捕获该类型的错误，还把其子类也“一网打尽”。比如：
try:
    foo()
except ValueError as e:
    print('ValueError')
except UnicodeError as e:
    print('UnicodeError')
第二个except永远也捕获不到UnicodeError，因为UnicodeError是ValueError的子类，如果有，也被第一个except给捕获了

6.
使用try...except捕获错误还有一个巨大的好处，就是可以跨越多层调用，比如函数main()调用foo()，foo()调用bar()，结果bar()出错了，这时，只要main()捕获到了，就可以处理

7.
也就是说，不需要在每个可能出错的地方去捕获错误，只要在合适的层次去捕获错误就可以了。这样一来，就大大减少了写try...except...finally的麻烦。

8.
调用栈
如果错误没有被捕获，它就会一直往上抛，最后被Python解释器捕获，打印一个错误信息，然后程序退出。出错的时候，一定要分析错误的调用栈信息，才能定位错误的位置。

9.
记录错误
如果不捕获错误，自然可以让Python解释器来打印出错误堆栈，但程序也被结束了。既然我们能捕获错误，就可以把错误堆栈打印出来，然后分析错误原因，同时，让程序继续执行下去。
Python内置的logging模块可以非常容易地记录错误信息
